Watching for file changes with StatReloader
System check identified some issues:

WARNINGS:
ml.Model.batch_size: (fields.W122) 'max_length' is ignored when used with IntegerField.
	HINT: Remove 'max_length' from field
ml.Model.epoch: (fields.W122) 'max_length' is ignored when used with IntegerField.
	HINT: Remove 'max_length' from field
ml.Model.test_x: (fields.W122) 'max_length' is ignored when used with IntegerField.
	HINT: Remove 'max_length' from field
ml.Model.train_x: (fields.W122) 'max_length' is ignored when used with IntegerField.
	HINT: Remove 'max_length' from field

System check identified 4 issues (0 silenced).
Watching for file changes with StatReloader
System check identified some issues:

WARNINGS:
ml.Model.batch_size: (fields.W122) 'max_length' is ignored when used with IntegerField.
	HINT: Remove 'max_length' from field
ml.Model.epoch: (fields.W122) 'max_length' is ignored when used with IntegerField.
	HINT: Remove 'max_length' from field
ml.Model.test_x: (fields.W122) 'max_length' is ignored when used with IntegerField.
	HINT: Remove 'max_length' from field
ml.Model.train_x: (fields.W122) 'max_length' is ignored when used with IntegerField.
	HINT: Remove 'max_length' from field

System check identified 4 issues (0 silenced).
Watching for file changes with StatReloader
System check identified some issues:

WARNINGS:
ml.Model.batch_size: (fields.W122) 'max_length' is ignored when used with IntegerField.
	HINT: Remove 'max_length' from field
ml.Model.epoch: (fields.W122) 'max_length' is ignored when used with IntegerField.
	HINT: Remove 'max_length' from field
ml.Model.test_x: (fields.W122) 'max_length' is ignored when used with IntegerField.
	HINT: Remove 'max_length' from field
ml.Model.train_x: (fields.W122) 'max_length' is ignored when used with IntegerField.
	HINT: Remove 'max_length' from field

System check identified 4 issues (0 silenced).
/root/ml/app/engine/api/v1/helpers.py:70: UnorderedObjectListWarning: Pagination may yield inconsistent results with an unordered object_list: <class 'ml.models.img_label.ImgLabel'> QuerySet.
  return Paginator(models, limit).page(page)
[12/May/2020 07:53:09] "GET /api/v1/img_label/search?name=&page=1&limit=30 HTTP/1.0" 200 551
[12/May/2020 07:53:11] "GET /api/v1/img_label/search?name=&page=1&limit=30 HTTP/1.0" 200 551
[12/May/2020 07:53:16] "GET /api/v1/img_label/search?name=&page=1&limit=30 HTTP/1.0" 200 551
[12/May/2020 07:53:18] "GET /api/v1/img_label/search?name=&page=1&limit=30 HTTP/1.0" 200 551
[12/May/2020 08:04:14] "GET /api/v1/img_label/search?name=&page=1&limit=30 HTTP/1.0" 200 551
[12/May/2020 08:04:15] "GET /api/v1/img_label/search?name=&page=1&limit=30 HTTP/1.0" 200 551
[12/May/2020 08:04:19] "OPTIONS /api/v1/img/handler HTTP/1.0" 200 0
[12/May/2020 08:04:19] "OPTIONS /api/v1/img/handler HTTP/1.0" 200 0
[12/May/2020 08:04:19] "OPTIONS /api/v1/img/handler HTTP/1.0" 200 0
[12/May/2020 08:04:19] "OPTIONS /api/v1/img/handler HTTP/1.0" 200 0
[12/May/2020 08:04:19] "OPTIONS /api/v1/img/handler HTTP/1.0" 200 0
[12/May/2020 08:04:19] "POST /api/v1/img/handler HTTP/1.0" 200 846089
[12/May/2020 08:04:19] "POST /api/v1/img/handler HTTP/1.0" 200 889009
[12/May/2020 08:04:20] "POST /api/v1/img/handler HTTP/1.0" 200 1680424
[12/May/2020 08:04:20] "POST /api/v1/img/handler HTTP/1.0" 200 1483772
[12/May/2020 08:04:20] "POST /api/v1/img/handler HTTP/1.0" 200 4865545
[12/May/2020 08:05:16] "POST /api/v1/img/handler HTTP/1.0" 200 889009
[12/May/2020 08:05:16] "POST /api/v1/img/handler HTTP/1.0" 200 846089
[12/May/2020 08:05:16] "POST /api/v1/img/handler HTTP/1.0" 200 1680424
[12/May/2020 08:05:16] "POST /api/v1/img/handler HTTP/1.0" 200 1483772
[12/May/2020 08:05:16] "POST /api/v1/img/handler HTTP/1.0" 200 4865545
[12/May/2020 08:11:36] "OPTIONS /api/v1/model/search?category=vgg16&name=&page=1&limit=30&order_by=register_time+desc HTTP/1.0" 200 0
Internal Server Error: /api/v1/model/search
Traceback (most recent call last):
  File "/usr/local/lib/python3.7/dist-packages/django/db/backends/base/base.py", line 220, in ensure_connection
    self.connect()
  File "/usr/local/lib/python3.7/dist-packages/django/utils/asyncio.py", line 26, in inner
    return func(*args, **kwargs)
  File "/usr/local/lib/python3.7/dist-packages/django/db/backends/base/base.py", line 197, in connect
    self.connection = self.get_new_connection(conn_params)
  File "/usr/local/lib/python3.7/dist-packages/django/utils/asyncio.py", line 26, in inner
    return func(*args, **kwargs)
  File "/usr/local/lib/python3.7/dist-packages/django/db/backends/mysql/base.py", line 233, in get_new_connection
    return Database.connect(**conn_params)
  File "/usr/local/lib/python3.7/dist-packages/MySQLdb/__init__.py", line 84, in Connect
    return Connection(*args, **kwargs)
  File "/usr/local/lib/python3.7/dist-packages/MySQLdb/connections.py", line 179, in __init__
    super(Connection, self).__init__(*args, **kwargs2)
MySQLdb._exceptions.OperationalError: (2003, "Can't connect to MySQL server on '127.0.0.1' (111)")

The above exception was the direct cause of the following exception:

Traceback (most recent call last):
  File "/usr/local/lib/python3.7/dist-packages/django/core/handlers/exception.py", line 34, in inner
    response = get_response(request)
  File "/usr/local/lib/python3.7/dist-packages/django/core/handlers/base.py", line 115, in _get_response
    response = self.process_exception_by_middleware(e, request)
  File "/usr/local/lib/python3.7/dist-packages/django/core/handlers/base.py", line 113, in _get_response
    response = wrapped_callback(request, *callback_args, **callback_kwargs)
  File "/root/ml/app/engine/api/v1/model.py", line 17, in search
    total = models.count()
  File "/usr/local/lib/python3.7/dist-packages/django/db/models/query.py", line 397, in count
    return self.query.get_count(using=self.db)
  File "/usr/local/lib/python3.7/dist-packages/django/db/models/sql/query.py", line 518, in get_count
    number = obj.get_aggregation(using, ['__count'])['__count']
  File "/usr/local/lib/python3.7/dist-packages/django/db/models/sql/query.py", line 503, in get_aggregation
    result = compiler.execute_sql(SINGLE)
  File "/usr/local/lib/python3.7/dist-packages/django/db/models/sql/compiler.py", line 1149, in execute_sql
    cursor = self.connection.cursor()
  File "/usr/local/lib/python3.7/dist-packages/django/utils/asyncio.py", line 26, in inner
    return func(*args, **kwargs)
  File "/usr/local/lib/python3.7/dist-packages/django/db/backends/base/base.py", line 260, in cursor
    return self._cursor()
  File "/usr/local/lib/python3.7/dist-packages/django/db/backends/base/base.py", line 236, in _cursor
    self.ensure_connection()
  File "/usr/local/lib/python3.7/dist-packages/django/utils/asyncio.py", line 26, in inner
    return func(*args, **kwargs)
  File "/usr/local/lib/python3.7/dist-packages/django/db/backends/base/base.py", line 220, in ensure_connection
    self.connect()
  File "/usr/local/lib/python3.7/dist-packages/django/db/utils.py", line 90, in __exit__
    raise dj_exc_value.with_traceback(traceback) from exc_value
  File "/usr/local/lib/python3.7/dist-packages/django/db/backends/base/base.py", line 220, in ensure_connection
    self.connect()
  File "/usr/local/lib/python3.7/dist-packages/django/utils/asyncio.py", line 26, in inner
    return func(*args, **kwargs)
  File "/usr/local/lib/python3.7/dist-packages/django/db/backends/base/base.py", line 197, in connect
    self.connection = self.get_new_connection(conn_params)
  File "/usr/local/lib/python3.7/dist-packages/django/utils/asyncio.py", line 26, in inner
    return func(*args, **kwargs)
  File "/usr/local/lib/python3.7/dist-packages/django/db/backends/mysql/base.py", line 233, in get_new_connection
    return Database.connect(**conn_params)
  File "/usr/local/lib/python3.7/dist-packages/MySQLdb/__init__.py", line 84, in Connect
    return Connection(*args, **kwargs)
  File "/usr/local/lib/python3.7/dist-packages/MySQLdb/connections.py", line 179, in __init__
    super(Connection, self).__init__(*args, **kwargs2)
django.db.utils.OperationalError: (2003, "Can't connect to MySQL server on '127.0.0.1' (111)")
[12/May/2020 08:11:36] "GET /api/v1/model/search?category=vgg16&name=&page=1&limit=30&order_by=register_time+desc HTTP/1.0" 500 213344
Internal Server Error: /api/v1/model/search
Traceback (most recent call last):
  File "/usr/local/lib/python3.7/dist-packages/django/db/backends/base/base.py", line 220, in ensure_connection
    self.connect()
  File "/usr/local/lib/python3.7/dist-packages/django/utils/asyncio.py", line 26, in inner
    return func(*args, **kwargs)
  File "/usr/local/lib/python3.7/dist-packages/django/db/backends/base/base.py", line 197, in connect
    self.connection = self.get_new_connection(conn_params)
  File "/usr/local/lib/python3.7/dist-packages/django/utils/asyncio.py", line 26, in inner
    return func(*args, **kwargs)
  File "/usr/local/lib/python3.7/dist-packages/django/db/backends/mysql/base.py", line 233, in get_new_connection
    return Database.connect(**conn_params)
  File "/usr/local/lib/python3.7/dist-packages/MySQLdb/__init__.py", line 84, in Connect
    return Connection(*args, **kwargs)
  File "/usr/local/lib/python3.7/dist-packages/MySQLdb/connections.py", line 179, in __init__
    super(Connection, self).__init__(*args, **kwargs2)
MySQLdb._exceptions.OperationalError: (2003, "Can't connect to MySQL server on '127.0.0.1' (111)")

The above exception was the direct cause of the following exception:

Traceback (most recent call last):
  File "/usr/local/lib/python3.7/dist-packages/django/core/handlers/exception.py", line 34, in inner
    response = get_response(request)
  File "/usr/local/lib/python3.7/dist-packages/django/core/handlers/base.py", line 115, in _get_response
    response = self.process_exception_by_middleware(e, request)
  File "/usr/local/lib/python3.7/dist-packages/django/core/handlers/base.py", line 113, in _get_response
    response = wrapped_callback(request, *callback_args, **callback_kwargs)
  File "/root/ml/app/engine/api/v1/model.py", line 17, in search
    total = models.count()
  File "/usr/local/lib/python3.7/dist-packages/django/db/models/query.py", line 397, in count
    return self.query.get_count(using=self.db)
  File "/usr/local/lib/python3.7/dist-packages/django/db/models/sql/query.py", line 518, in get_count
    number = obj.get_aggregation(using, ['__count'])['__count']
  File "/usr/local/lib/python3.7/dist-packages/django/db/models/sql/query.py", line 503, in get_aggregation
    result = compiler.execute_sql(SINGLE)
  File "/usr/local/lib/python3.7/dist-packages/django/db/models/sql/compiler.py", line 1149, in execute_sql
    cursor = self.connection.cursor()
  File "/usr/local/lib/python3.7/dist-packages/django/utils/asyncio.py", line 26, in inner
    return func(*args, **kwargs)
  File "/usr/local/lib/python3.7/dist-packages/django/db/backends/base/base.py", line 260, in cursor
    return self._cursor()
  File "/usr/local/lib/python3.7/dist-packages/django/db/backends/base/base.py", line 236, in _cursor
    self.ensure_connection()
  File "/usr/local/lib/python3.7/dist-packages/django/utils/asyncio.py", line 26, in inner
    return func(*args, **kwargs)
  File "/usr/local/lib/python3.7/dist-packages/django/db/backends/base/base.py", line 220, in ensure_connection
    self.connect()
  File "/usr/local/lib/python3.7/dist-packages/django/db/utils.py", line 90, in __exit__
    raise dj_exc_value.with_traceback(traceback) from exc_value
  File "/usr/local/lib/python3.7/dist-packages/django/db/backends/base/base.py", line 220, in ensure_connection
    self.connect()
  File "/usr/local/lib/python3.7/dist-packages/django/utils/asyncio.py", line 26, in inner
    return func(*args, **kwargs)
  File "/usr/local/lib/python3.7/dist-packages/django/db/backends/base/base.py", line 197, in connect
    self.connection = self.get_new_connection(conn_params)
  File "/usr/local/lib/python3.7/dist-packages/django/utils/asyncio.py", line 26, in inner
    return func(*args, **kwargs)
  File "/usr/local/lib/python3.7/dist-packages/django/db/backends/mysql/base.py", line 233, in get_new_connection
    return Database.connect(**conn_params)
  File "/usr/local/lib/python3.7/dist-packages/MySQLdb/__init__.py", line 84, in Connect
    return Connection(*args, **kwargs)
  File "/usr/local/lib/python3.7/dist-packages/MySQLdb/connections.py", line 179, in __init__
    super(Connection, self).__init__(*args, **kwargs2)
django.db.utils.OperationalError: (2003, "Can't connect to MySQL server on '127.0.0.1' (111)")
[12/May/2020 08:11:37] "GET /api/v1/model/search?category=vgg16&name=&page=1&limit=30&order_by=register_time+desc HTTP/1.0" 500 213344
